2022-07-25 22:20:16,695 ERROR: creating database dump error: local variable 'instance' referenced before assignment [in /home/goodnews/Documents/work_folder/osonwa/osonwa/tasks.py:48]
Traceback (most recent call last):
  File "/home/goodnews/Documents/work_folder/osonwa/osonwa/tasks.py", line 46, in create_feed_dump
    return create_dump_based_on_input_type(dump_input)
  File "/home/goodnews/Documents/work_folder/osonwa/osonwa/tasks.py", line 57, in create_dump_based_on_input_type
    return instance.id
UnboundLocalError: local variable 'instance' referenced before assignment
2022-07-25 22:21:02,002 ERROR: creating database dump error: local variable 'instance' referenced before assignment [in /home/goodnews/Documents/work_folder/osonwa/osonwa/tasks.py:48]
Traceback (most recent call last):
  File "/home/goodnews/Documents/work_folder/osonwa/osonwa/tasks.py", line 46, in create_feed_dump
    return create_dump_based_on_input_type(dump_input)
  File "/home/goodnews/Documents/work_folder/osonwa/osonwa/tasks.py", line 57, in create_dump_based_on_input_type
    return instance.id
UnboundLocalError: local variable 'instance' referenced before assignment
2022-07-25 22:21:31,788 ERROR: creating database dump error: local variable 'instance' referenced before assignment [in /home/goodnews/Documents/work_folder/osonwa/osonwa/tasks.py:48]
Traceback (most recent call last):
  File "/home/goodnews/Documents/work_folder/osonwa/osonwa/tasks.py", line 46, in create_feed_dump
    return create_dump_based_on_input_type(dump_input)
  File "/home/goodnews/Documents/work_folder/osonwa/osonwa/tasks.py", line 57, in create_dump_based_on_input_type
    return instance.id
UnboundLocalError: local variable 'instance' referenced before assignment
2022-07-25 22:25:20,216 ERROR: creating database dump error: local variable 'instance' referenced before assignment [in /home/goodnews/Documents/work_folder/osonwa/osonwa/tasks.py:48]
Traceback (most recent call last):
  File "/home/goodnews/Documents/work_folder/osonwa/osonwa/tasks.py", line 46, in create_feed_dump
    return create_dump_based_on_input_type(dump_input)
  File "/home/goodnews/Documents/work_folder/osonwa/osonwa/tasks.py", line 57, in create_dump_based_on_input_type
    return instance.id
UnboundLocalError: local variable 'instance' referenced before assignment
2022-07-25 22:25:43,444 ERROR: creating database dump error: local variable 'instance' referenced before assignment [in /home/goodnews/Documents/work_folder/osonwa/osonwa/tasks.py:48]
Traceback (most recent call last):
  File "/home/goodnews/Documents/work_folder/osonwa/osonwa/tasks.py", line 46, in create_feed_dump
    return create_dump_based_on_input_type(dump_input)
  File "/home/goodnews/Documents/work_folder/osonwa/osonwa/tasks.py", line 57, in create_dump_based_on_input_type
    return instance.id
UnboundLocalError: local variable 'instance' referenced before assignment
2022-07-25 22:26:09,371 ERROR: creating database dump error: local variable 'instance' referenced before assignment [in /home/goodnews/Documents/work_folder/osonwa/osonwa/tasks.py:49]
Traceback (most recent call last):
  File "/home/goodnews/Documents/work_folder/osonwa/osonwa/tasks.py", line 46, in create_feed_dump
    return create_dump_based_on_input_type(dump_input)
  File "/home/goodnews/Documents/work_folder/osonwa/osonwa/tasks.py", line 58, in create_dump_based_on_input_type
    return instance.id
UnboundLocalError: local variable 'instance' referenced before assignment
2022-07-26 14:49:13,612 ERROR: creating database dump error: local variable 'instance' referenced before assignment [in /home/goodnews/Documents/work_folder/osonwa/osonwa/tasks.py:48]
Traceback (most recent call last):
  File "/home/goodnews/Documents/work_folder/osonwa/osonwa/tasks.py", line 46, in create_feed_dump
    return create_dump_based_on_input_type(dump_input)
  File "/home/goodnews/Documents/work_folder/osonwa/osonwa/tasks.py", line 57, in create_dump_based_on_input_type
    return instance.id
UnboundLocalError: local variable 'instance' referenced before assignment
2022-07-26 14:50:27,993 ERROR: creating database dump error: local variable 'instance' referenced before assignment [in /home/goodnews/Documents/work_folder/osonwa/osonwa/tasks.py:48]
Traceback (most recent call last):
  File "/home/goodnews/Documents/work_folder/osonwa/osonwa/tasks.py", line 46, in create_feed_dump
    return create_dump_based_on_input_type(dump_input)
  File "/home/goodnews/Documents/work_folder/osonwa/osonwa/tasks.py", line 57, in create_dump_based_on_input_type
    return instance.id
UnboundLocalError: local variable 'instance' referenced before assignment
2022-07-26 14:50:45,536 ERROR: creating database dump error: local variable 'instance' referenced before assignment [in /home/goodnews/Documents/work_folder/osonwa/osonwa/tasks.py:48]
Traceback (most recent call last):
  File "/home/goodnews/Documents/work_folder/osonwa/osonwa/tasks.py", line 46, in create_feed_dump
    return create_dump_based_on_input_type(dump_input)
  File "/home/goodnews/Documents/work_folder/osonwa/osonwa/tasks.py", line 57, in create_dump_based_on_input_type
    return instance.id
UnboundLocalError: local variable 'instance' referenced before assignment
2022-07-26 14:51:54,726 ERROR: cpu celery exception from process_entry_and_return_dict_result....: time data 'time.struct_time(\n ' does not match format '%Y-%m-%dT%H:%M:%S' [in /home/goodnews/Documents/work_folder/osonwa/osonwa/helpers.py:267]
Traceback (most recent call last):
  File "/home/goodnews/Documents/work_folder/osonwa/osonwa/helpers.py", line 260, in process_entry_and_return_dict_result
    extract["date_published"] = entry_helper_object.get_date_published()
  File "/home/goodnews/Documents/work_folder/osonwa/osonwa/helpers.py", line 95, in get_date_published
    return self._to_datetime_object(published_date)
  File "/home/goodnews/Documents/work_folder/osonwa/osonwa/helpers.py", line 131, in _to_datetime_object
    return datetime.strptime(date_rep[:19], "%Y-%m-%dT%H:%M:%S")
  File "/usr/lib/python3.8/_strptime.py", line 568, in _strptime_datetime
    tt, fraction, gmtoff_fraction = _strptime(data_string, format)
  File "/usr/lib/python3.8/_strptime.py", line 349, in _strptime
    raise ValueError("time data %r does not match format %r" %
ValueError: time data 'time.struct_time(\n ' does not match format '%Y-%m-%dT%H:%M:%S'
2022-07-26 14:51:55,467 ERROR: cpu celery exception from process_entry_and_return_dict_result....: time data 'time.struct_time(\n ' does not match format '%Y-%m-%dT%H:%M:%S' [in /home/goodnews/Documents/work_folder/osonwa/osonwa/helpers.py:267]
Traceback (most recent call last):
  File "/home/goodnews/Documents/work_folder/osonwa/osonwa/helpers.py", line 260, in process_entry_and_return_dict_result
    extract["date_published"] = entry_helper_object.get_date_published()
  File "/home/goodnews/Documents/work_folder/osonwa/osonwa/helpers.py", line 95, in get_date_published
    return self._to_datetime_object(published_date)
  File "/home/goodnews/Documents/work_folder/osonwa/osonwa/helpers.py", line 131, in _to_datetime_object
    return datetime.strptime(date_rep[:19], "%Y-%m-%dT%H:%M:%S")
  File "/usr/lib/python3.8/_strptime.py", line 568, in _strptime_datetime
    tt, fraction, gmtoff_fraction = _strptime(data_string, format)
  File "/usr/lib/python3.8/_strptime.py", line 349, in _strptime
    raise ValueError("time data %r does not match format %r" %
ValueError: time data 'time.struct_time(\n ' does not match format '%Y-%m-%dT%H:%M:%S'
2022-07-26 14:51:56,433 ERROR: creating database dump error: local variable 'instance' referenced before assignment [in /home/goodnews/Documents/work_folder/osonwa/osonwa/tasks.py:48]
Traceback (most recent call last):
  File "/home/goodnews/Documents/work_folder/osonwa/osonwa/tasks.py", line 46, in create_feed_dump
    return create_dump_based_on_input_type(dump_input)
  File "/home/goodnews/Documents/work_folder/osonwa/osonwa/tasks.py", line 57, in create_dump_based_on_input_type
    return instance.id
UnboundLocalError: local variable 'instance' referenced before assignment
2022-07-26 14:53:45,988 ERROR: cpu celery exception from process_entry_and_return_dict_result....: time data 'time.struct_time(\n ' does not match format '%Y-%m-%dT%H:%M:%S' [in /home/goodnews/Documents/work_folder/osonwa/osonwa/helpers.py:267]
Traceback (most recent call last):
  File "/home/goodnews/Documents/work_folder/osonwa/osonwa/helpers.py", line 260, in process_entry_and_return_dict_result
    extract["date_published"] = entry_helper_object.get_date_published()
  File "/home/goodnews/Documents/work_folder/osonwa/osonwa/helpers.py", line 95, in get_date_published
    return self._to_datetime_object(published_date)
  File "/home/goodnews/Documents/work_folder/osonwa/osonwa/helpers.py", line 131, in _to_datetime_object
    return datetime.strptime(date_rep[:19], "%Y-%m-%dT%H:%M:%S")
  File "/usr/lib/python3.8/_strptime.py", line 568, in _strptime_datetime
    tt, fraction, gmtoff_fraction = _strptime(data_string, format)
  File "/usr/lib/python3.8/_strptime.py", line 349, in _strptime
    raise ValueError("time data %r does not match format %r" %
ValueError: time data 'time.struct_time(\n ' does not match format '%Y-%m-%dT%H:%M:%S'
2022-07-26 14:53:46,698 ERROR: cpu celery exception from process_entry_and_return_dict_result....: time data 'time.struct_time(\n ' does not match format '%Y-%m-%dT%H:%M:%S' [in /home/goodnews/Documents/work_folder/osonwa/osonwa/helpers.py:267]
Traceback (most recent call last):
  File "/home/goodnews/Documents/work_folder/osonwa/osonwa/helpers.py", line 260, in process_entry_and_return_dict_result
    extract["date_published"] = entry_helper_object.get_date_published()
  File "/home/goodnews/Documents/work_folder/osonwa/osonwa/helpers.py", line 95, in get_date_published
    return self._to_datetime_object(published_date)
  File "/home/goodnews/Documents/work_folder/osonwa/osonwa/helpers.py", line 131, in _to_datetime_object
    return datetime.strptime(date_rep[:19], "%Y-%m-%dT%H:%M:%S")
  File "/usr/lib/python3.8/_strptime.py", line 568, in _strptime_datetime
    tt, fraction, gmtoff_fraction = _strptime(data_string, format)
  File "/usr/lib/python3.8/_strptime.py", line 349, in _strptime
    raise ValueError("time data %r does not match format %r" %
ValueError: time data 'time.struct_time(\n ' does not match format '%Y-%m-%dT%H:%M:%S'
2022-07-26 14:53:47,783 ERROR: creating database dump error: local variable 'instance' referenced before assignment [in /home/goodnews/Documents/work_folder/osonwa/osonwa/tasks.py:48]
Traceback (most recent call last):
  File "/home/goodnews/Documents/work_folder/osonwa/osonwa/tasks.py", line 46, in create_feed_dump
    return create_dump_based_on_input_type(dump_input)
  File "/home/goodnews/Documents/work_folder/osonwa/osonwa/tasks.py", line 57, in create_dump_based_on_input_type
    return instance.id
UnboundLocalError: local variable 'instance' referenced before assignment
2022-07-26 14:54:37,544 ERROR: cpu celery exception from process_entry_and_return_dict_result....: time data 'time.struct_time(\n ' does not match format '%Y-%m-%dT%H:%M:%S' [in /home/goodnews/Documents/work_folder/osonwa/osonwa/helpers.py:267]
Traceback (most recent call last):
  File "/home/goodnews/Documents/work_folder/osonwa/osonwa/helpers.py", line 260, in process_entry_and_return_dict_result
    extract["date_published"] = entry_helper_object.get_date_published()
  File "/home/goodnews/Documents/work_folder/osonwa/osonwa/helpers.py", line 95, in get_date_published
    return self._to_datetime_object(published_date)
  File "/home/goodnews/Documents/work_folder/osonwa/osonwa/helpers.py", line 131, in _to_datetime_object
    return datetime.strptime(date_rep[:19], "%Y-%m-%dT%H:%M:%S")
  File "/usr/lib/python3.8/_strptime.py", line 568, in _strptime_datetime
    tt, fraction, gmtoff_fraction = _strptime(data_string, format)
  File "/usr/lib/python3.8/_strptime.py", line 349, in _strptime
    raise ValueError("time data %r does not match format %r" %
ValueError: time data 'time.struct_time(\n ' does not match format '%Y-%m-%dT%H:%M:%S'
2022-07-26 14:54:38,268 ERROR: cpu celery exception from process_entry_and_return_dict_result....: time data 'time.struct_time(\n ' does not match format '%Y-%m-%dT%H:%M:%S' [in /home/goodnews/Documents/work_folder/osonwa/osonwa/helpers.py:267]
Traceback (most recent call last):
  File "/home/goodnews/Documents/work_folder/osonwa/osonwa/helpers.py", line 260, in process_entry_and_return_dict_result
    extract["date_published"] = entry_helper_object.get_date_published()
  File "/home/goodnews/Documents/work_folder/osonwa/osonwa/helpers.py", line 95, in get_date_published
    return self._to_datetime_object(published_date)
  File "/home/goodnews/Documents/work_folder/osonwa/osonwa/helpers.py", line 131, in _to_datetime_object
    return datetime.strptime(date_rep[:19], "%Y-%m-%dT%H:%M:%S")
  File "/usr/lib/python3.8/_strptime.py", line 568, in _strptime_datetime
    tt, fraction, gmtoff_fraction = _strptime(data_string, format)
  File "/usr/lib/python3.8/_strptime.py", line 349, in _strptime
    raise ValueError("time data %r does not match format %r" %
ValueError: time data 'time.struct_time(\n ' does not match format '%Y-%m-%dT%H:%M:%S'
2022-07-26 14:54:39,392 ERROR: creating database dump error: local variable 'instance' referenced before assignment [in /home/goodnews/Documents/work_folder/osonwa/osonwa/tasks.py:48]
Traceback (most recent call last):
  File "/home/goodnews/Documents/work_folder/osonwa/osonwa/tasks.py", line 46, in create_feed_dump
    return create_dump_based_on_input_type(dump_input)
  File "/home/goodnews/Documents/work_folder/osonwa/osonwa/tasks.py", line 57, in create_dump_based_on_input_type
    return instance.id
UnboundLocalError: local variable 'instance' referenced before assignment
2022-07-26 14:55:36,536 ERROR: cpu celery exception from process_entry_and_return_dict_result....: time data 'time.struct_time(\n ' does not match format '%Y-%m-%dT%H:%M:%S' [in /home/goodnews/Documents/work_folder/osonwa/osonwa/helpers.py:267]
Traceback (most recent call last):
  File "/home/goodnews/Documents/work_folder/osonwa/osonwa/helpers.py", line 260, in process_entry_and_return_dict_result
    extract["date_published"] = entry_helper_object.get_date_published()
  File "/home/goodnews/Documents/work_folder/osonwa/osonwa/helpers.py", line 95, in get_date_published
    return self._to_datetime_object(published_date)
  File "/home/goodnews/Documents/work_folder/osonwa/osonwa/helpers.py", line 131, in _to_datetime_object
    return datetime.strptime(date_rep[:19], "%Y-%m-%dT%H:%M:%S")
  File "/usr/lib/python3.8/_strptime.py", line 568, in _strptime_datetime
    tt, fraction, gmtoff_fraction = _strptime(data_string, format)
  File "/usr/lib/python3.8/_strptime.py", line 349, in _strptime
    raise ValueError("time data %r does not match format %r" %
ValueError: time data 'time.struct_time(\n ' does not match format '%Y-%m-%dT%H:%M:%S'
2022-07-26 14:55:37,238 ERROR: cpu celery exception from process_entry_and_return_dict_result....: time data 'time.struct_time(\n ' does not match format '%Y-%m-%dT%H:%M:%S' [in /home/goodnews/Documents/work_folder/osonwa/osonwa/helpers.py:267]
Traceback (most recent call last):
  File "/home/goodnews/Documents/work_folder/osonwa/osonwa/helpers.py", line 260, in process_entry_and_return_dict_result
    extract["date_published"] = entry_helper_object.get_date_published()
  File "/home/goodnews/Documents/work_folder/osonwa/osonwa/helpers.py", line 95, in get_date_published
    return self._to_datetime_object(published_date)
  File "/home/goodnews/Documents/work_folder/osonwa/osonwa/helpers.py", line 131, in _to_datetime_object
    return datetime.strptime(date_rep[:19], "%Y-%m-%dT%H:%M:%S")
  File "/usr/lib/python3.8/_strptime.py", line 568, in _strptime_datetime
    tt, fraction, gmtoff_fraction = _strptime(data_string, format)
  File "/usr/lib/python3.8/_strptime.py", line 349, in _strptime
    raise ValueError("time data %r does not match format %r" %
ValueError: time data 'time.struct_time(\n ' does not match format '%Y-%m-%dT%H:%M:%S'
2022-07-26 14:55:38,527 ERROR: creating database dump error: local variable 'instance' referenced before assignment [in /home/goodnews/Documents/work_folder/osonwa/osonwa/tasks.py:48]
Traceback (most recent call last):
  File "/home/goodnews/Documents/work_folder/osonwa/osonwa/tasks.py", line 46, in create_feed_dump
    return create_dump_based_on_input_type(dump_input)
  File "/home/goodnews/Documents/work_folder/osonwa/osonwa/tasks.py", line 57, in create_dump_based_on_input_type
    return instance.id
UnboundLocalError: local variable 'instance' referenced before assignment
2022-07-26 15:01:15,316 ERROR: cpu celery exception from process_entry_and_return_dict_result....: time data 'time.struct_time(\n ' does not match format '%Y-%m-%dT%H:%M:%S' [in /home/goodnews/Documents/work_folder/osonwa/osonwa/helpers.py:267]
Traceback (most recent call last):
  File "/home/goodnews/Documents/work_folder/osonwa/osonwa/helpers.py", line 260, in process_entry_and_return_dict_result
    extract["date_published"] = entry_helper_object.get_date_published()
  File "/home/goodnews/Documents/work_folder/osonwa/osonwa/helpers.py", line 95, in get_date_published
    return self._to_datetime_object(published_date)
  File "/home/goodnews/Documents/work_folder/osonwa/osonwa/helpers.py", line 131, in _to_datetime_object
    return datetime.strptime(date_rep[:19], "%Y-%m-%dT%H:%M:%S")
  File "/usr/lib/python3.8/_strptime.py", line 568, in _strptime_datetime
    tt, fraction, gmtoff_fraction = _strptime(data_string, format)
  File "/usr/lib/python3.8/_strptime.py", line 349, in _strptime
    raise ValueError("time data %r does not match format %r" %
ValueError: time data 'time.struct_time(\n ' does not match format '%Y-%m-%dT%H:%M:%S'
2022-07-26 15:01:16,054 ERROR: cpu celery exception from process_entry_and_return_dict_result....: time data 'time.struct_time(\n ' does not match format '%Y-%m-%dT%H:%M:%S' [in /home/goodnews/Documents/work_folder/osonwa/osonwa/helpers.py:267]
Traceback (most recent call last):
  File "/home/goodnews/Documents/work_folder/osonwa/osonwa/helpers.py", line 260, in process_entry_and_return_dict_result
    extract["date_published"] = entry_helper_object.get_date_published()
  File "/home/goodnews/Documents/work_folder/osonwa/osonwa/helpers.py", line 95, in get_date_published
    return self._to_datetime_object(published_date)
  File "/home/goodnews/Documents/work_folder/osonwa/osonwa/helpers.py", line 131, in _to_datetime_object
    return datetime.strptime(date_rep[:19], "%Y-%m-%dT%H:%M:%S")
  File "/usr/lib/python3.8/_strptime.py", line 568, in _strptime_datetime
    tt, fraction, gmtoff_fraction = _strptime(data_string, format)
  File "/usr/lib/python3.8/_strptime.py", line 349, in _strptime
    raise ValueError("time data %r does not match format %r" %
ValueError: time data 'time.struct_time(\n ' does not match format '%Y-%m-%dT%H:%M:%S'
2022-07-26 15:02:45,528 ERROR: cpu celery exception from process_entry_and_return_dict_result....: time data 'time.struct_time(\n ' does not match format '%Y-%m-%dT%H:%M:%S' [in /home/goodnews/Documents/work_folder/osonwa/osonwa/helpers.py:267]
Traceback (most recent call last):
  File "/home/goodnews/Documents/work_folder/osonwa/osonwa/helpers.py", line 260, in process_entry_and_return_dict_result
    extract["date_published"] = entry_helper_object.get_date_published()
  File "/home/goodnews/Documents/work_folder/osonwa/osonwa/helpers.py", line 95, in get_date_published
    return self._to_datetime_object(published_date)
  File "/home/goodnews/Documents/work_folder/osonwa/osonwa/helpers.py", line 131, in _to_datetime_object
    return datetime.strptime(date_rep[:19], "%Y-%m-%dT%H:%M:%S")
  File "/usr/lib/python3.8/_strptime.py", line 568, in _strptime_datetime
    tt, fraction, gmtoff_fraction = _strptime(data_string, format)
  File "/usr/lib/python3.8/_strptime.py", line 349, in _strptime
    raise ValueError("time data %r does not match format %r" %
ValueError: time data 'time.struct_time(\n ' does not match format '%Y-%m-%dT%H:%M:%S'
2022-07-26 15:02:46,241 ERROR: cpu celery exception from process_entry_and_return_dict_result....: time data 'time.struct_time(\n ' does not match format '%Y-%m-%dT%H:%M:%S' [in /home/goodnews/Documents/work_folder/osonwa/osonwa/helpers.py:267]
Traceback (most recent call last):
  File "/home/goodnews/Documents/work_folder/osonwa/osonwa/helpers.py", line 260, in process_entry_and_return_dict_result
    extract["date_published"] = entry_helper_object.get_date_published()
  File "/home/goodnews/Documents/work_folder/osonwa/osonwa/helpers.py", line 95, in get_date_published
    return self._to_datetime_object(published_date)
  File "/home/goodnews/Documents/work_folder/osonwa/osonwa/helpers.py", line 131, in _to_datetime_object
    return datetime.strptime(date_rep[:19], "%Y-%m-%dT%H:%M:%S")
  File "/usr/lib/python3.8/_strptime.py", line 568, in _strptime_datetime
    tt, fraction, gmtoff_fraction = _strptime(data_string, format)
  File "/usr/lib/python3.8/_strptime.py", line 349, in _strptime
    raise ValueError("time data %r does not match format %r" %
ValueError: time data 'time.struct_time(\n ' does not match format '%Y-%m-%dT%H:%M:%S'
2022-07-26 15:03:13,634 ERROR: cpu celery exception from process_entry_and_return_dict_result....: time data 'time.struct_time(\n ' does not match format '%Y-%m-%dT%H:%M:%S' [in /home/goodnews/Documents/work_folder/osonwa/osonwa/helpers.py:267]
Traceback (most recent call last):
  File "/home/goodnews/Documents/work_folder/osonwa/osonwa/helpers.py", line 260, in process_entry_and_return_dict_result
    extract["date_published"] = entry_helper_object.get_date_published()
  File "/home/goodnews/Documents/work_folder/osonwa/osonwa/helpers.py", line 95, in get_date_published
    return self._to_datetime_object(published_date)
  File "/home/goodnews/Documents/work_folder/osonwa/osonwa/helpers.py", line 131, in _to_datetime_object
    return datetime.strptime(date_rep[:19], "%Y-%m-%dT%H:%M:%S")
  File "/usr/lib/python3.8/_strptime.py", line 568, in _strptime_datetime
    tt, fraction, gmtoff_fraction = _strptime(data_string, format)
  File "/usr/lib/python3.8/_strptime.py", line 349, in _strptime
    raise ValueError("time data %r does not match format %r" %
ValueError: time data 'time.struct_time(\n ' does not match format '%Y-%m-%dT%H:%M:%S'
2022-07-26 15:03:14,332 ERROR: cpu celery exception from process_entry_and_return_dict_result....: time data 'time.struct_time(\n ' does not match format '%Y-%m-%dT%H:%M:%S' [in /home/goodnews/Documents/work_folder/osonwa/osonwa/helpers.py:267]
Traceback (most recent call last):
  File "/home/goodnews/Documents/work_folder/osonwa/osonwa/helpers.py", line 260, in process_entry_and_return_dict_result
    extract["date_published"] = entry_helper_object.get_date_published()
  File "/home/goodnews/Documents/work_folder/osonwa/osonwa/helpers.py", line 95, in get_date_published
    return self._to_datetime_object(published_date)
  File "/home/goodnews/Documents/work_folder/osonwa/osonwa/helpers.py", line 131, in _to_datetime_object
    return datetime.strptime(date_rep[:19], "%Y-%m-%dT%H:%M:%S")
  File "/usr/lib/python3.8/_strptime.py", line 568, in _strptime_datetime
    tt, fraction, gmtoff_fraction = _strptime(data_string, format)
  File "/usr/lib/python3.8/_strptime.py", line 349, in _strptime
    raise ValueError("time data %r does not match format %r" %
ValueError: time data 'time.struct_time(\n ' does not match format '%Y-%m-%dT%H:%M:%S'
2022-07-26 15:03:37,216 ERROR: cpu celery exception from process_entry_and_return_dict_result....: time data 'time.struct_time(\n ' does not match format '%Y-%m-%dT%H:%M:%S' [in /home/goodnews/Documents/work_folder/osonwa/osonwa/helpers.py:267]
Traceback (most recent call last):
  File "/home/goodnews/Documents/work_folder/osonwa/osonwa/helpers.py", line 260, in process_entry_and_return_dict_result
    extract["date_published"] = entry_helper_object.get_date_published()
  File "/home/goodnews/Documents/work_folder/osonwa/osonwa/helpers.py", line 95, in get_date_published
    return self._to_datetime_object(published_date)
  File "/home/goodnews/Documents/work_folder/osonwa/osonwa/helpers.py", line 131, in _to_datetime_object
    return datetime.strptime(date_rep[:19], "%Y-%m-%dT%H:%M:%S")
  File "/usr/lib/python3.8/_strptime.py", line 568, in _strptime_datetime
    tt, fraction, gmtoff_fraction = _strptime(data_string, format)
  File "/usr/lib/python3.8/_strptime.py", line 349, in _strptime
    raise ValueError("time data %r does not match format %r" %
ValueError: time data 'time.struct_time(\n ' does not match format '%Y-%m-%dT%H:%M:%S'
2022-07-26 15:03:37,957 ERROR: cpu celery exception from process_entry_and_return_dict_result....: time data 'time.struct_time(\n ' does not match format '%Y-%m-%dT%H:%M:%S' [in /home/goodnews/Documents/work_folder/osonwa/osonwa/helpers.py:267]
Traceback (most recent call last):
  File "/home/goodnews/Documents/work_folder/osonwa/osonwa/helpers.py", line 260, in process_entry_and_return_dict_result
    extract["date_published"] = entry_helper_object.get_date_published()
  File "/home/goodnews/Documents/work_folder/osonwa/osonwa/helpers.py", line 95, in get_date_published
    return self._to_datetime_object(published_date)
  File "/home/goodnews/Documents/work_folder/osonwa/osonwa/helpers.py", line 131, in _to_datetime_object
    return datetime.strptime(date_rep[:19], "%Y-%m-%dT%H:%M:%S")
  File "/usr/lib/python3.8/_strptime.py", line 568, in _strptime_datetime
    tt, fraction, gmtoff_fraction = _strptime(data_string, format)
  File "/usr/lib/python3.8/_strptime.py", line 349, in _strptime
    raise ValueError("time data %r does not match format %r" %
ValueError: time data 'time.struct_time(\n ' does not match format '%Y-%m-%dT%H:%M:%S'
